Workbook

Sheet Summary
A1: Real-source ingestion test (spec 0006), re-run after the spec 0007 fixes (A1) and with extractor v4 (A2, spec 0008)
A2: Satisfaction rule (fixed before results): Good = Hit@5 at least 90% and the run published; Acceptable = Hit@5 at least 75%; Poor = otherwise, or the run did not publish.
A4: Round | B4: What changed | C4: Source | D4: Answerable questions | E4: Hit@1 | F4: Hit@5 | G4: Hit@1 % | H4: Hit@5 % | I4: Run published | J4: Satisfaction
A5: R1 | B5: Recommended settings (v2) | C5: W1 | D5: =COUNTIFS(Retrieval!$A$2:$A$402,A5,Retrieval!$B$2:$B$402,C5,Retrieval!$I$2:$I$402,"<>n/a") | E5: =COUNTIFS(Retrieval!$A$2:$A$402,A5,Retrieval!$B$2:$B$402,C5,Retrieval!$I$2:$I$402,"yes") | F5: =COUNTIFS(Retrieval!$A$2:$A$402,A5,Retrieval!$B$2:$B$402,C5,Retrieval!$J$2:$J$402,"yes") | G5: =IF(D5=0,0,E5/D5) | H5: =IF(D5=0,0,F5/D5) | I5: =IF(COUNTIFS(Structure!$A:$A,A5,Structure!$C:$C,C5,Structure!$D:$D,"succeeded")>0,"yes","no") | J5: =IF(I5="no","Poor (not published)",IF(H5>=0.9,"Good",IF(H5>=0.75,"Acceptable","Poor")))
A6: R1 | B6: Recommended settings (v2) | C6: W2 | D6: =COUNTIFS(Retrieval!$A$2:$A$402,A6,Retrieval!$B$2:$B$402,C6,Retrieval!$I$2:$I$402,"<>n/a") | E6: =COUNTIFS(Retrieval!$A$2:$A$402,A6,Retrieval!$B$2:$B$402,C6,Retrieval!$I$2:$I$402,"yes") | F6: =COUNTIFS(Retrieval!$A$2:$A$402,A6,Retrieval!$B$2:$B$402,C6,Retrieval!$J$2:$J$402,"yes") | G6: =IF(D6=0,0,E6/D6) | H6: =IF(D6=0,0,F6/D6) | I6: =IF(COUNTIFS(Structure!$A:$A,A6,Structure!$C:$C,C6,Structure!$D:$D,"succeeded")>0,"yes","no") | J6: =IF(I6="no","Poor (not published)",IF(H6>=0.9,"Good",IF(H6>=0.75,"Acceptable","Poor")))
A7: R1 | B7: Recommended settings (v2) | C7: W3 | D7: =COUNTIFS(Retrieval!$A$2:$A$402,A7,Retrieval!$B$2:$B$402,C7,Retrieval!$I$2:$I$402,"<>n/a") | E7: =COUNTIFS(Retrieval!$A$2:$A$402,A7,Retrieval!$B$2:$B$402,C7,Retrieval!$I$2:$I$402,"yes") | F7: =COUNTIFS(Retrieval!$A$2:$A$402,A7,Retrieval!$B$2:$B$402,C7,Retrieval!$J$2:$J$402,"yes") | G7: =IF(D7=0,0,E7/D7) | H7: =IF(D7=0,0,F7/D7) | I7: =IF(COUNTIFS(Structure!$A:$A,A7,Structure!$C:$C,C7,Structure!$D:$D,"succeeded")>0,"yes","no") | J7: =IF(I7="no","Poor (not published)",IF(H7>=0.9,"Good",IF(H7>=0.75,"Acceptable","Poor")))
A8: R1 | B8: Recommended settings (v2) | C8: W4 | D8: =COUNTIFS(Retrieval!$A$2:$A$402,A8,Retrieval!$B$2:$B$402,C8,Retrieval!$I$2:$I$402,"<>n/a") | E8: =COUNTIFS(Retrieval!$A$2:$A$402,A8,Retrieval!$B$2:$B$402,C8,Retrieval!$I$2:$I$402,"yes") | F8: =COUNTIFS(Retrieval!$A$2:$A$402,A8,Retrieval!$B$2:$B$402,C8,Retrieval!$J$2:$J$402,"yes") | G8: =IF(D8=0,0,E8/D8) | H8: =IF(D8=0,0,F8/D8) | I8: =IF(COUNTIFS(Structure!$A:$A,A8,Structure!$C:$C,C8,Structure!$D:$D,"succeeded")>0,"yes","no") | J8: =IF(I8="no","Poor (not published)",IF(H8>=0.9,"Good",IF(H8>=0.75,"Acceptable","Poor")))
A9: R5 | B9: Publish the other pages and show warnings | C9: W1 | D9: =COUNTIFS(Retrieval!$A$2:$A$402,A9,Retrieval!$B$2:$B$402,C9,Retrieval!$I$2:$I$402,"<>n/a") | E9: =COUNTIFS(Retrieval!$A$2:$A$402,A9,Retrieval!$B$2:$B$402,C9,Retrieval!$I$2:$I$402,"yes") | F9: =COUNTIFS(Retrieval!$A$2:$A$402,A9,Retrieval!$B$2:$B$402,C9,Retrieval!$J$2:$J$402,"yes") | G9: =IF(D9=0,0,E9/D9) | H9: =IF(D9=0,0,F9/D9) | I9: =IF(COUNTIFS(Structure!$A:$A,A9,Structure!$C:$C,C9,Structure!$D:$D,"succeeded")>0,"yes","no") | J9: =IF(I9="no","Poor (not published)",IF(H9>=0.9,"Good",IF(H9>=0.75,"Acceptable","Poor")))
A10: R5 | B10: Publish the other pages and show warnings | C10: W2 | D10: =COUNTIFS(Retrieval!$A$2:$A$402,A10,Retrieval!$B$2:$B$402,C10,Retrieval!$I$2:$I$402,"<>n/a") | E10: =COUNTIFS(Retrieval!$A$2:$A$402,A10,Retrieval!$B$2:$B$402,C10,Retrieval!$I$2:$I$402,"yes") | F10: =COUNTIFS(Retrieval!$A$2:$A$402,A10,Retrieval!$B$2:$B$402,C10,Retrieval!$J$2:$J$402,"yes") | G10: =IF(D10=0,0,E10/D10) | H10: =IF(D10=0,0,F10/D10) | I10: =IF(COUNTIFS(Structure!$A:$A,A10,Structure!$C:$C,C10,Structure!$D:$D,"succeeded")>0,"yes","no") | J10: =IF(I10="no","Poor (not published)",IF(H10>=0.9,"Good",IF(H10>=0.75,"Acceptable","Poor")))
A11: R5 | B11: Publish the other pages and show warnings | C11: W3 | D11: =COUNTIFS(Retrieval!$A$2:$A$402,A11,Retrieval!$B$2:$B$402,C11,Retrieval!$I$2:$I$402,"<>n/a") | E11: =COUNTIFS(Retrieval!$A$2:$A$402,A11,Retrieval!$B$2:$B$402,C11,Retrieval!$I$2:$I$402,"yes") | F11: =COUNTIFS(Retrieval!$A$2:$A$402,A11,Retrieval!$B$2:$B$402,C11,Retrieval!$J$2:$J$402,"yes") | G11: =IF(D11=0,0,E11/D11) | H11: =IF(D11=0,0,F11/D11) | I11: =IF(COUNTIFS(Structure!$A:$A,A11,Structure!$C:$C,C11,Structure!$D:$D,"succeeded")>0,"yes","no") | J11: =IF(I11="no","Poor (not published)",IF(H11>=0.9,"Good",IF(H11>=0.75,"Acceptable","Poor")))
A12: R5 | B12: Publish the other pages and show warnings | C12: W4 | D12: =COUNTIFS(Retrieval!$A$2:$A$402,A12,Retrieval!$B$2:$B$402,C12,Retrieval!$I$2:$I$402,"<>n/a") | E12: =COUNTIFS(Retrieval!$A$2:$A$402,A12,Retrieval!$B$2:$B$402,C12,Retrieval!$I$2:$I$402,"yes") | F12: =COUNTIFS(Retrieval!$A$2:$A$402,A12,Retrieval!$B$2:$B$402,C12,Retrieval!$J$2:$J$402,"yes") | G12: =IF(D12=0,0,E12/D12) | H12: =IF(D12=0,0,F12/D12) | I12: =IF(COUNTIFS(Structure!$A:$A,A12,Structure!$C:$C,C12,Structure!$D:$D,"succeeded")>0,"yes","no") | J12: =IF(I12="no","Poor (not published)",IF(H12>=0.9,"Good",IF(H12>=0.75,"Acceptable","Poor")))
A13: R6 | B13: Chunks 300/400/40 | C13: W1 | D13: =COUNTIFS(Retrieval!$A$2:$A$402,A13,Retrieval!$B$2:$B$402,C13,Retrieval!$I$2:$I$402,"<>n/a") | E13: =COUNTIFS(Retrieval!$A$2:$A$402,A13,Retrieval!$B$2:$B$402,C13,Retrieval!$I$2:$I$402,"yes") | F13: =COUNTIFS(Retrieval!$A$2:$A$402,A13,Retrieval!$B$2:$B$402,C13,Retrieval!$J$2:$J$402,"yes") | G13: =IF(D13=0,0,E13/D13) | H13: =IF(D13=0,0,F13/D13) | I13: =IF(COUNTIFS(Structure!$A:$A,A13,Structure!$C:$C,C13,Structure!$D:$D,"succeeded")>0,"yes","no") | J13: =IF(I13="no","Poor (not published)",IF(H13>=0.9,"Good",IF(H13>=0.75,"Acceptable","Poor")))
A14: R6 | B14: Chunks 300/400/40 | C14: W2 | D14: =COUNTIFS(Retrieval!$A$2:$A$402,A14,Retrieval!$B$2:$B$402,C14,Retrieval!$I$2:$I$402,"<>n/a") | E14: =COUNTIFS(Retrieval!$A$2:$A$402,A14,Retrieval!$B$2:$B$402,C14,Retrieval!$I$2:$I$402,"yes") | F14: =COUNTIFS(Retrieval!$A$2:$A$402,A14,Retrieval!$B$2:$B$402,C14,Retrieval!$J$2:$J$402,"yes") | G14: =IF(D14=0,0,E14/D14) | H14: =IF(D14=0,0,F14/D14) | I14: =IF(COUNTIFS(Structure!$A:$A,A14,Structure!$C:$C,C14,Structure!$D:$D,"succeeded")>0,"yes","no") | J14: =IF(I14="no","Poor (not published)",IF(H14>=0.9,"Good",IF(H14>=0.75,"Acceptable","Poor")))
A15: R6 | B15: Chunks 300/400/40 | C15: W3 | D15: =COUNTIFS(Retrieval!$A$2:$A$402,A15,Retrieval!$B$2:$B$402,C15,Retrieval!$I$2:$I$402,"<>n/a") | E15: =COUNTIFS(Retrieval!$A$2:$A$402,A15,Retrieval!$B$2:$B$402,C15,Retrieval!$I$2:$I$402,"yes") | F15: =COUNTIFS(Retrieval!$A$2:$A$402,A15,Retrieval!$B$2:$B$402,C15,Retrieval!$J$2:$J$402,"yes") | G15: =IF(D15=0,0,E15/D15) | H15: =IF(D15=0,0,F15/D15) | I15: =IF(COUNTIFS(Structure!$A:$A,A15,Structure!$C:$C,C15,Structure!$D:$D,"succeeded")>0,"yes","no") | J15: =IF(I15="no","Poor (not published)",IF(H15>=0.9,"Good",IF(H15>=0.75,"Acceptable","Poor")))
A16: R6 | B16: Chunks 300/400/40 | C16: W4 | D16: =COUNTIFS(Retrieval!$A$2:$A$402,A16,Retrieval!$B$2:$B$402,C16,Retrieval!$I$2:$I$402,"<>n/a") | E16: =COUNTIFS(Retrieval!$A$2:$A$402,A16,Retrieval!$B$2:$B$402,C16,Retrieval!$I$2:$I$402,"yes") | F16: =COUNTIFS(Retrieval!$A$2:$A$402,A16,Retrieval!$B$2:$B$402,C16,Retrieval!$J$2:$J$402,"yes") | G16: =IF(D16=0,0,E16/D16) | H16: =IF(D16=0,0,F16/D16) | I16: =IF(COUNTIFS(Structure!$A:$A,A16,Structure!$C:$C,C16,Structure!$D:$D,"succeeded")>0,"yes","no") | J16: =IF(I16="no","Poor (not published)",IF(H16>=0.9,"Good",IF(H16>=0.75,"Acceptable","Poor")))
... A66: A3 | B66: Extract v5: recommended | C66: G8 | D66: =COUNTIFS(Retrieval!$A$2:$A$402,A66,Retrieval!$B$2:$B$402,C66,Retrieval!$I$2:$I$402,"<>n/a") | E66: =COUNTIFS(Retrieval!$A$2:$A$402,A66,Retrieval!$B$2:$B$402,C66,Retrieval!$I$2:$I$402,"yes") | F66: =COUNTIFS(Retrieval!$A$2:$A$402,A66,Retrieval!$B$2:$B$402,C66,Retrieval!$J$2:$J$402,"yes") | G66: =IF(D66=0,0,E66/D66) | H66: =IF(D66=0,0,F66/D66) | I66: =IF(COUNTIFS(Structure!$A:$A,A66,Structure!$C:$C,C66,Structure!$D:$D,"succeeded")>0,"yes","no") | J66: =IF(I66="no","Poor (not published)",IF(H66>=0.9,"Good",IF(H66>=0.75,"Acceptable","Poor")))
A68: Total embedding estimate (USD) | D68: =Runs!S20
A69: Total answer cost (USD) | D69: =Answers!K120
A70: Total spend (USD, embedding upper bound + recorded answers) | D70: =D68+D69
A71: Spending cap (USD) | D71: 1
A73: Recommendation
A74: Keep visible: If a file can't be read well, Languages in scanned pages, Chunk size (target / maximum / overlap).
A75: Keep in Advanced: Extractor version (v1 / v2), Maximum OCR pages, Quality thresholds (empty pages, characters, OCR confidence, reading order, malformed tables), Language policy (allowlist, confidence, mixed languages).
A76: Candidate to remove: Read scanned pages (OCR), OCR resolution (DPI), Per-page OCR timeout, Detect rotation / deskew, Extraction strategy (Auto / Native / Layout-aware), Table evidence (Structured + Markdown / Markdown / Plain text).
A77: Fix first: X1 The recommended setting ('Stop and let me review') blocks an ordinary government report. | X2 Borderless PDF tables lose their rows: whole columns are merged into one cell, and cells over 1,000 characters are cut. | X3 'Publish the other files and show warnings' does not publish the others when a file cannot be read.

Sheet Sources
A1: ID | B1: Type | C1: Name | D1: URL(s) | E1: Licence | F1: Scope | G1: Fetched on | H1: SHA-256 (files)
A2: W1 | B2: Website | C2: Python tutorial | D2: https://docs.python.org/3/tutorial/ | E2: PSF documentation licence (PSF License Agreement) | F2: Crawl from https://docs.python.org/3/tutorial/, depth 1, at most 20 pages | G2: 2026-10-09
A3: W2 | B3: Website | C3: Wikipedia articles | D3: https://en.wikipedia.org/wiki/Solar_System https://en.wikipedia.org/wiki/Moon https://en.wikipedia.org/wiki/Mount_Everest https://en.wikipedia.org/wiki/Great_Barrier_Reef https://en.wikipedia.org/wiki/Amazon_River https://en.wikipedia.org/wiki/Photosynthesis https://en.wikipedia.org/wiki/Periodic_table https://en.wikipedia.org/wiki/Olympic_Games https://en.wikipedia.org/wiki/Euro https://en.wikipedia.org/wiki/Python_(programming_language) | E3: CC BY-SA 4.0 | F3: 10 listed URLs | G3: 2026-10-09
A4: W3 | B4: Website | C4: GOV.UK guidance | D4: https://www.gov.uk/national-minimum-wage-rates https://www.gov.uk/holiday-entitlement-rights https://www.gov.uk/maternity-pay-leave https://www.gov.uk/statutory-sick-pay https://www.gov.uk/redundancy-your-rights https://www.gov.uk/flexible-working https://www.gov.uk/calculate-your-redundancy-pay https://www.gov.uk/council-tax-bands https://www.gov.uk/vehicle-tax-rate-tables https://www.gov.uk/income-tax-rates | E4: Open Government Licence v3.0 | F4: 10 listed URLs | G4: 2026-10-09
A5: W4 | B5: Website | C5: MDN Web Docs | D5: https://developer.mozilla.org/en-US/docs/Web/HTTP/Reference/Status https://developer.mozilla.org/en-US/docs/Web/HTTP/Reference/Methods https://developer.mozilla.org/en-US/docs/Web/HTTP/Reference/Headers/Cache-Control https://developer.mozilla.org/en-US/docs/Web/JavaScript/Reference/Global_Objects/Array https://developer.mozilla.org/en-US/docs/Web/JavaScript/Guide/Closures https://developer.mozilla.org/en-US/docs/Web/CSS/Reference/Properties/display https://developer.mozilla.org/en-US/docs/Web/API/Fetch_API https://developer.mozilla.org/en-US/docs/Web/HTML/Reference/Elements/table https://developer.mozilla.org/en-US/docs/Web/CSS/Guides/Grid_layout https://developer.mozilla.org/en-US/docs/Web/HTTP/Guides/CORS | E5: CC BY-SA 2.5 | F5: 10 listed URLs | G5: 2026-10-09
A6: F1 | B6: File (PDF) | C6: BERT (NAACL 2019), two-column paper | D6: https://aclanthology.org/N19-1423.pdf | E6: CC BY 4.0 (ACL Anthology, papers from 2016 onward) | F6: 16 pages | G6: 2026-10-09 | H6: 987545ffb087f1ece898142c403a516baeabeb70ce19089397fac6f7db12c3d4
A7: F2 | B7: File (PDF) | C7: US Census Bureau P60-279, Income in the United States: 2022 | D7: https://www.census.gov/content/dam/Census/library/publications/2023/demo/p60-279.pdf | E7: Public domain (US federal government work) | F7: 62 pages | G7: 2026-10-09 | H7: ce921ae1c54b000b3c1defbe52762a5358b9b597a6cd01aee5b84671fab598c5
A8: F3 | B8: File (PDF) | C8: Surveyor VI mission report, JPL TR 32-1262 Part III, scanned pages 7-16 | D8: https://sic.lpl.arizona.edu/sites/sic.lpl.arizona.edu/files/surveyor/Surveyor_VI_NASA-TechnicalReport32-1262_Part-3.pdf | E8: NASA/JPL technical report, US government work; 10-page extract made locally without altering the scan images | F8: 10 pages | G8: 2026-10-09 | H8: e6b37144235757381364229a5c937246ec68727704564651401fba417a5da745
A9: F4 | B9: File (PDF) | C9: Eurostat, Chiffres clés sur l'Europe, édition 2019 (French) | D9: https://ec.europa.eu/eurostat/documents/3217494/10164473/KS-EI-19-001-FR_N.pdf/aef66e0b-f5fe-c4e1-67ac-3c3f01a44384 | E9: © European Union, 2019; reuse authorised with attribution (Commission Decision 2011/833/EU) | F9: 76 pages | G9: 2026-10-10 | H9: 9457b14c2fb44527eeb718ba7753bc5781d771db2b88447a723a42c65b5776af
A10: F5 | B10: File (PDF) | C10: USGS Circular 115, Estimated use of water in the United States, 1950 (1951 scan), image-only copy | D10: https://pubs.usgs.gov/circ/1951/0115/report.pdf | E10: Public domain (US federal government work) | F10: 16 pages | G10: 2026-10-10 | H10: 7c1d9fe14a6c7d7d065bfc3d018ef32fefc692ce36524dace01fd0908a181c23
A11: F6 | B11: File (DOCX) | C11: DfT, Local highways maintenance transparency report template (DOCX) | D11: https://assets.publishing.service.gov.uk/media/6a26d314f56856fd11c0b191/highways-maintenance-reports-template.docx | E11: Open Government Licence v3.0 | G11: 2026-10-10 | H11: eb468aeba7ed8ff0bac3382ddeaa8e56dc859bc9dc3d988d4389a1fe508dfc02
A12: F7 | B12: File (PPTX) | C12: Home Office/DfE, Designing and building a Prevent risk assessment (PPTX, 14 slides, 3 tables) | D12: https://assets.publishing.service.gov.uk/media/60a3d4a7d3bf7f28855b8ffd/Designing_and_building_a_Prevent_risk_assessment.pptx | E12: Open Government Licence v3.0 | F12: 14 pages | G12: 2026-10-10 | H12: 71e2e0fe0eacbb94867329cae876e1f119e8d2e7f76145cf289d12cb7873484f
A13: G1 | B13: File (PDF) | C13: IRS Form W-4 (2026), Employee's Withholding Certificate (form with worksheets and tables) | D13: https://www.irs.gov/pub/irs-pdf/fw4.pdf | E13: Public domain (US federal government work) | F13: 5 pages | G13: 2026-10-10 | H13: 92444d8856ce55d9e25dca8b6d1420634fc68b11e1ab1f760916ea29ddd312b2
A14: G2 | B14: File (PDF) | C14: NIST SP 800-63B, Digital Identity Guidelines: Authentication and Lifecycle Management (2017, updated 2020; withdrawn 2025 and kept for history) | D14: https://nvlpubs.nist.gov/nistpubs/SpecialPublications/NIST.SP.800-63b.pdf | E14: Public domain (US federal government work) | F14: 80 pages | G14: 2026-10-10 | H14: ccfce7510a1267933f912d023306c6e7d485f21be63d271108b61aad6139127e
A15: G3 | B15: File (PDF) | C15: GAO-23-900494, Fiscal Year 2024 Budget Request (testimony with charts and tables) | D15: https://www.gao.gov/assets/gao-23-900494.pdf | E15: Public domain (US federal government work; GAO notes third-party images may be copyrighted) | F15: 20 pages | G15: 2026-10-10 | H15: 7ae5716dd9fb8792c59eb1c4d623d33c13f505b914229b62b0932c151f6f8f88
A16: G4 | B16: File (PDF) | C16: Executive Order 9066 (1942), first page, typed scan, image-only copy | D16: https://www.archives.gov/files/milestone-documents/images/doc-074-big.jpg | E16: Public domain (US federal government record, National Archives) | F16: 1 pages | G16: 2026-10-10 | H16: 2c7e202d431a762814ccdde34ff7c04b1d1a154d6bb1e02f2ad67a1a687f9096
A17: G5 | B17: File (XLSX) | C17: NISRA, Labour Force Survey quarterly tables, October to December 2023 (XLSX, 27 sheets) | D17: https://www.nisra.gov.uk/system/files/statistics/lmr-labour-force-survey-quarterly-tables-october-december-2023.xlsx | E17: Open Government Licence v3.0 (NISRA) | G17: 2026-10-10 | H17: 29a67242b51a9efcd349da8d7d03bf05d3ca479b462374954db44d4e55b907de
A18: G6 | B18: File (PPTX) | C18: ECGD, organisation chart and pay data, September 2012 (PPTX, 3 slides) | D18: https://www.gov.uk/government/uploads/system/uploads/attachment_data/file/190924/ecgd-structure-chart-september-2012.pptx | E18: Open Government Licence (data.gov.uk record) | F18: 3 pages | G18: 2026-10-10 | H18: 1f1192e07415540cdd422d8cb1c0e4fd851af43cb5c63341e867cb7188dda596
A19: G7 | B19: File (DOCX) | C19: DfE, Information sharing agreement template for childminder agencies and local authorities (DOCX) | D19: https://assets.publishing.service.gov.uk/media/69a988838fd807b03bbe92d0/Information_sharing_agreement_template_for_childminder_agencies_and_local_authorities.docx | E19: Open Government Licence v3.0 | G19: 2026-10-10 | H19: 6bc63fd49da37883f35c007ab6ad9a5fdf6b5daf3bd0b0155b35e1c3d04b0a65
A20: G8 | B20: File (PDF) | C20: Pan et al. (2023), Sex difference in driving speed management, PLOS ONE 18(7): e0288653 | D20: https://journals.plos.org/plosone/article/file?id=10.1371/journal.pone.0288653&type=printable | E20: CC BY 4.0 | F20: 14 pages | G20: 2026-10-10 | H20: 0fe1665514be2c545374fd80ffac056d85dca33076960650515d52f68c4df886

Sheet Runs
A1: Round | B1: Track | C1: What changed | D1: Extractor | E1: OCR | F1: OCR DPI | G1: Max OCR pages | H1: Table evidence | I1: If a file can't be read well | J1: Chunk target / max / overlap | K1: Website pages | L1: Status | M1: Error | N1: Items ready | O1: Items failed | P1: Items excluded | Q1: Chunks | R1: Duration (s) | S1: Embedding cost est. (USD) | T1: Embedding tokens (app-reported) | U1: Embedding cost (app-reported, USD)
A2: R1 | B2: files | C2: Recommended settings (v2) | D2: layout-ocr-v2 | E2: auto | F2: 200 | G2: 50 | H2: preserve | I2: Stop and let me review | J2: 600 / 800 / 80 | K2: n/a | L2: failed | M2: One or more selected files could not be processed. Inspect run items and retry with a new run. | N2: 0 | O2: 1 | P2: 0 | Q2: 159 | R2: 0 | T2: not recorded | U2: not recorded
A3: R1 | B3: web | C3: Recommended settings (v2) | D3: n/a (HTML) | E3: n/a | F3: n/a | G3: n/a | H3: n/a (HTML) | I3: Stop and let me review | J3: 600 / 800 / 80 | K3: Fetched live | L3: succeeded | N3: 92 | O3: 0 | P3: 0 | Q3: 3209 | R3: 430 | S3: 0.040144 | T3: not recorded | U3: not recorded
A4: R1w | B4: files | C4: Recommended, publish others with warnings | D4: layout-ocr-v2 | E4: auto | F4: 200 | G4: 50 | H4: preserve | I4: Publish the other files and show warnings | J4: 600 / 800 / 80 | K4: n/a | L4: succeeded | N4: 3 | O4: 0 | P4: 0 | Q4: 718 | R4: 94 | S4: 0.009012 | T4: not recorded | U4: not recorded
A5: R2 | B5: files | C5: Extractor layout-ocr-v1 | D5: layout-ocr-v1 | E5: auto | F5: 200 | G5: 50 | H5: preserve | I5: Publish the other files and show warnings | J5: 600 / 800 / 80 | K5: n/a | L5: succeeded | N5: 3 | O5: 0 | P5: 0 | Q5: 758 | R5: 90 | S5: 0.006846 | T5: not recorded | U5: not recorded
A6: R3a | B6: files | C6: OCR 300 DPI, 100 pages | D6: layout-ocr-v2 | E6: auto | F6: 300 | G6: 100 | H6: preserve | I6: Publish the other files and show warnings | J6: 600 / 800 / 80 | K6: n/a | L6: succeeded | N6: 3 | O6: 0 | P6: 0 | Q6: 718 | R6: 42 | S6: 0.009012 | T6: not recorded | U6: not recorded
A7: R3b | B7: files | C7: OCR off | D7: layout-ocr-v2 | E7: off | F7: 200 | G7: 50 | H7: preserve | I7: Publish the other files and show warnings | J7: 600 / 800 / 80 | K7: n/a | L7: failed | M7: One or more selected files could not be processed. Inspect run items and retry with a new run. | N7: 0 | O7: 1 | P7: 0 | Q7: 159 | R7: 0 | T7: not recorded | U7: not recorded
A8: R4 | B8: files | C8: Table evidence plain text | D8: layout-ocr-v2 | E8: auto | F8: 200 | G8: 50 | H8: plain_text | I8: Publish the other files and show warnings | J8: 600 / 800 / 80 | K8: n/a | L8: succeeded | N8: 3 | O8: 0 | P8: 0 | Q8: 684 | R8: 60 | S8: 0.008456 | T8: not recorded | U8: not recorded
A9: R5 | B9: web | C9: Publish the other pages and show warnings | D9: n/a (HTML) | E9: n/a | F9: n/a | G9: n/a | H9: n/a (HTML) | I9: Publish the other files and show warnings | J9: 600 / 800 / 80 | K9: Reused R1 snapshot | L9: succeeded | N9: 47 | O9: 0 | P9: 0 | Q9: 3209 | R9: 81 | S9: 0.040144 | T9: not recorded | U9: not recorded
A10: R6 | B10: files | C10: Chunks 300/400/40 | D10: layout-ocr-v2 | E10: auto | F10: 200 | G10: 50 | H10: preserve | I10: Publish the other files and show warnings | J10: 300 / 400 / 40 | K10: n/a | L10: succeeded | N10: 3 | O10: 0 | P10: 0 | Q10: 1593 | R10: 222 | S10: 0.013111 | T10: not recorded | U10: not recorded
A11: R6 | B11: web | C11: Chunks 300/400/40 | D11: n/a (HTML) | E11: n/a | F11: n/a | G11: n/a | H11: n/a (HTML) | I11: Stop and let me review | J11: 300 / 400 / 40 | K11: Reused R1 snapshot | L11: succeeded | N11: 47 | O11: 0 | P11: 0 | Q11: 6198 | R11: 688 | S11: 0.043422 | T11: not recorded | U11: not recorded
A12: A1 | B12: files | C12: After fixes: recommended (v3) | D12: layout-ocr-v3 | E12: auto | F12: 200 | G12: 50 | H12: preserve | I12: Stop and let me review | J12: 600 / 800 / 80 | K12: n/a | L12: succeeded | N12: 3 | O12: 0 | P12: 0 | Q12: 698 | R12: 14 | S12: 0.008666 | T12: 0 | U12: 0
A13: A1 | B13: web | C13: After fixes: recommended (v3) | D13: n/a (HTML) | E13: n/a | F13: n/a | G13: n/a | H13: n/a (HTML) | I13: Publish the other files and show warnings | J13: 600 / 800 / 80 | K13: Reused R1 snapshot | L13: succeeded | N13: 47 | O13: 0 | P13: 0 | Q13: 2381 | R13: 237 | S13: 0.028906 | T13: 137559 | U13: 0.00275118
A14: A2 | B14: files | C14: Extract v4: recommended | D14: layout-ocr-v4 | E14: auto | F14: 200 | G14: 100 | H14: preserve | I14: Stop and let me review | J14: 600 / 800 / 80 | K14: n/a | L14: succeeded | N14: 3 | O14: 0 | P14: 0 | Q14: 637 | R14: 85 | S14: 0.007748 | T14: 57835 | U14: 0.0011567
A15: A2 | B15: new | C15: Extract v4: recommended | D15: layout-ocr-v4 | E15: auto | F15: 200 | G15: 100 | H15: preserve | I15: Publish the other files and show warnings | J15: 600 / 800 / 80 | K15: n/a | L15: succeeded | N15: 4 | O15: 0 | P15: 0 | Q15: 1030 | R15: 168 | S15: 0.005961 | T15: 94681 | U15: 0.00189362
A16: A3 | B16: d2 | C16: Extract v5: recommended | D16: layout-ocr-v5 | E16: auto | F16: 200 | G16: 100 | H16: preserve | I16: Publish the other files and show warnings | J16: 600 / 800 / 80 | K16: n/a | L16: succeeded | N16: 8 | O16: 0 | P16: 0 | Q16: 844 | R16: 155 | S16: 0.009523 | T16: 110195 | U16: 0.0022039
A17: A3 | B17: files | C17: Extract v5: recommended | D17: layout-ocr-v5 | E17: auto | F17: 200 | G17: 100 | H17: preserve | I17: Stop and let me review | J17: 600 / 800 / 80 | K17: n/a | L17: succeeded | N17: 3 | O17: 0 | P17: 0 | Q17: 707 | R17: 72 | S17: 0.009333 | T17: 87675 | U17: 0.0017535
A18: A3 | B18: new | C18: Extract v5: recommended | D18: layout-ocr-v5 | E18: auto | F18: 200 | G18: 100 | H18: preserve | I18: Stop and let me review | J18: 600 / 800 / 80 | K18: n/a | L18: succeeded | N18: 4 | O18: 0 | P18: 0 | Q18: 1025 | R18: 64 | S18: 0.004786 | T18: 7873 | U18: 0.00015746
A20: Total embedding estimate (USD) | S20: =SUM(S2:S18)
A21: Estimate basis: indexed UTF-8 bytes x $0.02 per million (OpenRouter list price for openai/text-embedding-3-small, 2026-10-09). Bytes overstate tokens, so this is an upper bound. From A1 (spec 0007) the app records the provider-reported usage; earlier runs show 'not recorded'.

Sheet Structure
A1: Round | B1: Track | C1: Source | D1: Run status | E1: Items | F1: Items ready | G1: Items failed | H1: Items excluded | I1: Pages or URLs indexed | J1: Chunks | K1: Median chunk tokens | L1: Max chunk tokens | M1: Chunks with section path (%) | N1: Table chunks (pipe rows) | O1: Table chunks with header | P1: Short single-line chunks
A2: R1 | B2: files | C2: F1 | D2: failed | E2: 1 | F2: 0 | G2: 0 | H2: 0 | I2: 0 | J2: 0 | N2: 0 | O2: 0 | P2: 0
A3: R1 | B3: files | C3: F2 | D3: failed | E3: 1 | F3: 0 | G3: 1 | H3: 0 | I3: 0 | J3: 0 | N3: 0 | O3: 0 | P3: 0
A4: R1 | B4: files | C4: F3 | D4: failed | E4: 1 | F4: 0 | G4: 0 | H4: 0 | I4: 0 | J4: 0 | N4: 0 | O4: 0 | P4: 0
A5: R1 | B5: web | C5: W1 | D5: succeeded | E5: 56 | F5: 56 | G5: 0 | H5: 0 | I5: 17 | J5: 465 | K5: 616 | L5: 800 | M5: 96.3 | N5: 0 | O5: 0 | P5: 8
A6: R1 | B6: web | C6: W2 | D6: succeeded | E6: 10 | F6: 10 | G6: 0 | H6: 0 | I6: 10 | J6: 2288 | K6: 632 | L6: 800 | M6: 100 | N6: 0 | O6: 0 | P6: 25
A7: R1 | B7: web | C7: W3 | D7: succeeded | E7: 10 | F7: 10 | G7: 0 | H7: 0 | I7: 10 | J7: 57 | K7: 290 | L7: 710 | M7: 70.2 | N7: 0 | O7: 0 | P7: 8
A8: R1 | B8: web | C8: W4 | D8: succeeded | E8: 10 | F8: 10 | G8: 0 | H8: 0 | I8: 10 | J8: 399 | K8: 542 | L8: 796 | M8: 97.7 | N8: 0 | O8: 0 | P8: 22
A9: R1w | B9: files | C9: F1 | D9: succeeded | E9: 1 | F9: 1 | G9: 0 | H9: 0 | I9: 16 | J9: 159 | K9: 575 | L9: 795 | M9: 100 | N9: 6 | O9: 6 | P9: 4
A10: R1w | B10: files | C10: F2 | D10: succeeded | E10: 1 | F10: 1 | G10: 0 | H10: 0 | I10: 62 | J10: 536 | K10: 644.5 | L10: 800 | M10: 99.8 | N10: 232 | O10: 232 | P10: 7
A11: R1w | B11: files | C11: F3 | D11: succeeded | E11: 1 | F11: 1 | G11: 0 | H11: 0 | I11: 9 | J11: 23 | K11: 543 | L11: 799 | M11: 0 | N11: 0 | O11: 0 | P11: 1
A12: R2 | B12: files | C12: F1 | D12: succeeded | E12: 1 | F12: 1 | G12: 0 | H12: 0 | I12: 16 | J12: 189 | K12: 390 | L12: 795 | M12: 31.7 | N12: 5 | O12: 5 | P12: 12
A13: R2 | B13: files | C13: F2 | D13: succeeded | E13: 1 | F13: 1 | G13: 0 | H13: 0 | I13: 62 | J13: 545 | K13: 533 | L13: 800 | M13: 27.5 | N13: 149 | O13: 149 | P13: 45
A14: R2 | B14: files | C14: F3 | D14: succeeded | E14: 1 | F14: 1 | G14: 0 | H14: 0 | I14: 9 | J14: 24 | K14: 622 | L14: 654 | M14: 0 | N14: 0 | O14: 0 | P14: 1
A15: R3a | B15: files | C15: F1 | D15: succeeded | E15: 1 | F15: 1 | G15: 0 | H15: 0 | I15: 16 | J15: 159 | K15: 575 | L15: 795 | M15: 100 | N15: 6 | O15: 6 | P15: 4
A16: R3a | B16: files | C16: F2 | D16: succeeded | E16: 1 | F16: 1 | G16: 0 | H16: 0 | I16: 62 | J16: 536 | K16: 644.5 | L16: 800 | M16: 99.8 | N16: 232 | O16: 232 | P16: 7
A17: R3a | B17: files | C17: F3 | D17: succeeded | E17: 1 | F17: 1 | G17: 0 | H17: 0 | I17: 9 | J17: 23 | K17: 543 | L17: 799 | M17: 0 | N17: 0 | O17: 0 | P17: 1
A18: R3b | B18: files | C18: F1 | D18: failed | E18: 1 | F18: 0 | G18: 0 | H18: 0 | I18: 0 | J18: 0 | N18: 0 | O18: 0 | P18: 0
A19: R3b | B19: files | C19: F2 | D19: failed | E19: 1 | F19: 0 | G19: 0 | H19: 0 | I19: 0 | J19: 0 | N19: 0 | O19: 0 | P19: 0
A20: R3b | B20: files | C20: F3 | D20: failed | E20: 1 | F20: 0 | G20: 1 | H20: 0 | I20: 0 | J20: 0 | N20: 0 | O20: 0 | P20: 0
A21: R4 | B21: files | C21: F1 | D21: succeeded | E21: 1 | F21: 1 | G21: 0 | H21: 0 | I21: 16 | J21: 156 | K21: 572.5 | L21: 795 | M21: 100 | N21: 0 | O21: 0 | P21: 4
A22: R4 | B22: files | C22: F2 | D22: succeeded | E22: 1 | F22: 1 | G22: 0 | H22: 0 | I22: 62 | J22: 505 | K22: 636 | L22: 800 | M22: 99.8 | N22: 0 | O22: 0 | P22: 8
A23: R4 | B23: files | C23: F3 | D23: succeeded | E23: 1 | F23: 1 | G23: 0 | H23: 0 | I23: 9 | J23: 23 | K23: 543 | L23: 799 | M23: 0 | N23: 0 | O23: 0 | P23: 1
A24: R5 | B24: web | C24: W1 | D24: succeeded | E24: 17 | F24: 17 | G24: 0 | H24: 0 | I24: 17 | J24: 465 | K24: 616 | L24: 800 | M24: 96.3 | N24: 0 | O24: 0 | P24: 8
A25: R5 | B25: web | C25: W2 | D25: succeeded | E25: 10 | F25: 10 | G25: 0 | H25: 0 | I25: 10 | J25: 2288 | K25: 632 | L25: 800 | M25: 100 | N25: 0 | O25: 0 | P25: 25
A26: R5 | B26: web | C26: W3 | D26: succeeded | E26: 10 | F26: 10 | G26: 0 | H26: 0 | I26: 10 | J26: 57 | K26: 290 | L26: 710 | M26: 70.2 | N26: 0 | O26: 0 | P26: 8
A27: R5 | B27: web | C27: W4 | D27: succeeded | E27: 10 | F27: 10 | G27: 0 | H27: 0 | I27: 10 | J27: 399 | K27: 542 | L27: 796 | M27: 97.7 | N27: 0 | O27: 0 | P27: 22
A28: R6 | B28: files | C28: F1 | D28: succeeded | E28: 1 | F28: 1 | G28: 0 | H28: 0 | I28: 16 | J28: 275 | K28: 302 | L28: 400 | M28: 100 | N28: 10 | O28: 10 | P28: 4
A29: R6 | B29: files | C29: F2 | D29: succeeded | E29: 1 | F29: 1 | G29: 0 | H29: 0 | I29: 62 | J29: 1276 | K29: 378 | L29: 400 | M29: 99.9 | N29: 755 | O29: 755 | P29: 15
A30: R6 | B30: files | C30: F3 | D30: succeeded | E30: 1 | F30: 1 | G30: 0 | H30: 0 | I30: 9 | J30: 42 | K30: 315.5 | L30: 397 | M30: 0 | N30: 0 | O30: 0 | P30: 2
A31: R6 | B31: web | C31: W1 | D31: succeeded | E31: 17 | F31: 17 | G31: 0 | H31: 0 | I31: 17 | J31: 898 | K31: 318 | L31: 400 | M31: 100 | N31: 0 | O31: 0 | P31: 38
A32: R6 | B32: web | C32: W2 | D32: succeeded | E32: 10 | F32: 10 | G32: 0 | H32: 0 | I32: 10 | J32: 4506 | K32: 317 | L32: 400 | M32: 100 | N32: 0 | O32: 0 | P32: 58
... A63: A3 | B63: new | C63: F7 | D63: succeeded | E63: 1 | F63: 1 | G63: 0 | H63: 0 | I63: 14 | J63: 15 | K63: 378 | L63: 785 | M63: 0 | N63: 2 | O63: 2 | P63: 5

Sheet Retrieval
A1: Round | B1: Source | C1: Question ID | D1: Question | E1: Kind | F1: Expected phrase(s) | G1: Index used (round) | H1: First hit rank | I1: Hit@1 | J1: Hit@5 | K1: Top result source | L1: Top result section | M1: Top result excerpt
A2: R1 | B2: W1 | C2: w1-q1 | D2: Which class does the Python tutorial recommend for implementing a queue? | E2: text | F2: collections.deque | G2: R1 | H2: 2 | I2: no | J2: yes | K2: https://docs.python.org/3/tutorial/datastructures.html | L2: 5. Data Structures ¶ > 5.1. More on Lists ¶ > 5.1.2. Using Lists as Queues ¶ | M2: e which was designed to have fast appends and pops from both ends. For example: >>> from collections import deque >>> queue = deque(["Eric", "John", "Michael"]) >>> queue.append("Terry") # Terry arrives >>> queue.append("Graham")
A3: R1 | B3: W1 | C3: w1-q2 | D3: In CPython 3.3, where is the compiled version of a module named spam.py cached? | E3: code | F3: spam.cpython-33.pyc | G3: R1 | H3: 1 | I3: yes | J3: yes | K3: https://docs.python.org/3/tutorial/modules.html | L3: 6. Modules ¶ > 6.1. More on Modules ¶ | M3: 6.1.3. “Compiled” Python files ¶ To speed up loading modules, Python caches the compiled version of each module in the __pycache__ directory under the name module.version.pyc, where the version encodes the format of the compiled file; it generally c
A4: R1 | B4: W1 | C4: w1-q3 | D4: What command does the tutorial use to create a virtual environment called tutorial-env? | E4: code | F4: python -m venv tutorial-env | G4: R1 | H4: 1 | I4: yes | J4: yes | K4: https://docs.python.org/3/tutorial/venv.html | L4: 12. Virtual Environments and Packages ¶ | M4: 12.2. Creating Virtual Environments ¶ The module used to create and manage virtual environments is called venv. venv will install the Python version from which the command was run (as reported by the --version option). For instance, executing the c
A5: R1 | B5: W1 | C5: w1-q4 | D5: When is the else clause of a for loop executed? | E5: text | F5: if no break occurred | G5: R1 | H5: 2 | I5: no | J5: yes | K5: https://docs.python.org/3/tutorial/controlflow.html | L5: 4. More Control Flow Tools ¶ > 4.5. else Clauses on Loops ¶ | M5: . Look closely: the else clause belongs to the for loop, not the if statement.) One way to think of the else clause is to imagine it paired with the if inside the loop. As the loop executes, it will run a sequence like if/if/if/else. The if is ins
A6: R1 | B6: W1 | C6: w1-q5 | D6: What does the pass statement do? | E6: text | F6: the pass statement does nothing | G6: R1 | H6: 1 | I6: yes | J6: yes | K6: https://docs.python.org/3/tutorial/controlflow.html | L6: 4. More Control Flow Tools ¶ | M6: 4.6. pass Statements ¶ The pass statement does nothing. It can be used when a statement is required syntactically but the program requires no action. For example: >>> while True: ... pass # Busy-wait for keyboard interrupt (Ctrl+C) ... This i
A7: R1 | B7: W1 | C7: w1-q6 | D7: What does the list index() method return? | E7: list | F7: zero-based index of the first occurrence | G7: R1 | H7: 3 | I7: no | J7: yes | K7: https://developer.mozilla.org/en-US/docs/Web/JavaScript/Reference/Global_Objects/Array | L7: Array > Description > Iterative methods | M7: Note the following: Not all methods do the i in this test. The find, findIndex, findLast, and findLastIndex methods do not, but other methods do. The length is memorized before the loop starts. This affects how insertions and deletions during itera
A8: R1 | B8: W1 | C8: w1-q7 | D8: What is the short name for formatted string literals? | E8: text | F8: also called f-strings | G8: R1 | H8: 2 | I8: no | J8: yes | K8: https://docs.python.org/3/tutorial/inputoutput.html | L8: 7. Input and Output ¶ > 7.1. Fancier Output Formatting ¶ > 7.1.1. Formatted String Literals ¶ | M8: a minimum number of characters wide. This is useful for making columns line up. >>> table = {'Sjoerd': 4127, 'Jack': 4098, 'Dcab': 7678} >>> for name, phone in table.items(): ... print(f'{name:10} ==> {phone:10d}') ... Sjoerd ==> 4127
A9: R1 | B9: W1 | C9: w1-q8 | D9: On what date will Python 4.0 be released according to the tutorial? | E9: unanswerable | F9: (not in source) | G9: R1 | I9: n/a | J9: n/a | K9: https://en.wikipedia.org/wiki/Python_(programming_language) | L9: Python (programming language) > References | M9: ↑ "Python Developer's Guide – Python Developer's Guide". devguide.python.org. Archived from the original on 9 November 2020. Retrieved 17 December 2019. ↑ Hughes, Owen (24 May 2021). "Programming languages: Why Python 4.0 might never arrive, accordi
A10: R1 | B10: W2 | C10: w2-q1 | D10: What is the elevation of Mount Everest in metres? | E10: table | F10: 8,848.86 m | G10: R1 | H10: 2 | I10: no | J10: yes | K10: https://en.wikipedia.org/wiki/Mount_Everest | L10: Mount Everest > Surveys | M10: 21st century On 9 October 2005, after several months of measurement and calculation, the Chinese Academy of Sciences and State Bureau of Surveying and Mapping announced the height of Everest as 8,844.43 m (29,017.16 ft) with accuracy of ±0.21 m (8.3
A11: R1 | B11: W2 | C11: w2-q2 | D11: How many individual reefs make up the Great Barrier Reef? | E11: text | F11: over 2,900 individual reefs | G11: R1 | I11: no | J11: no | K11: https://en.wikipedia.org/wiki/Great_Barrier_Reef | L11: Great Barrier Reef | M11: The reef is located in the Coral Sea, off the coast of Queensland, Australia. It is separated from the coast by a channel 160 kilometres (100 mi) wide in places and over 61 metres (200 ft) deep.[7] The Great Barrier Reef can be seen from outer sp
A12: R1 | B12: W2 | C12: w2-q3 | D12: What is the average discharge of the Amazon River? | E12: text | F12: 215,000 to 230,000 cubic meters per second | G12: R1 | H12: 2 | I12: no | J12: yes | K12: https://en.wikipedia.org/wiki/Amazon_River | L12: Amazon River > Discharge | M12: Average discharge at the estuary; Period from 2003 to 2015: 7,200 km3/a (230,000 m3/s)[80][81] Year (km3) (m3/s) Year (km3) (m3/s) 2003 6,470 205,000 2010 6,464 205,000 2004 6,747 214,000 2011 7,378 234,000 2005 6,522 207,000 20
A13: R1 | B13: W2 | C13: w2-q4 | D13: When was the euro introduced to world financial markets as an accounting currency? | E13: text | F13: 1 january 1999 | G13: R1 | H13: 1 | I13: yes | J13: yes | K13: https://en.wikipedia.org/wiki/Euro | L13: Euro | M13: hest combined values of banknotes and coins in circulation in the world.[15][16] The name euro was officially adopted on 16 December 1995 in Madrid.[17] The euro was introduced to world financial markets as an accounting currency on 1 January 1999,
A14: R1 | B14: W2 | C14: w2-q5 | D14: Who published the first generally accepted periodic table, and in what year? | E14: text | F14: dmitri mendeleev in 1869 | G14: R1 | H14: 1 | I14: yes | J14: yes | K14: https://en.wikipedia.org/wiki/Periodic_table | L14: Periodic table | M14: The first periodic table to become generally accepted was that of the Russian chemist Dmitri Mendeleev in 1869; he formulated the periodic law as a dependence of chemical properties on atomic mass. As not all elements were then known, there were gaps
A15: R1 | B15: W2 | C15: w2-q6 | D15: What is the Moon's average distance from Earth? | E15: text | F15: 378,000 kilometers | G15: R1 | I15: no | J15: no | K15: https://en.wikipedia.org/wiki/Moon | L15: Moon > Explanatory notes | M15: ↑ The mean distance of the Moon from the Earth is 384401 {\displaystyle 384401} km. The equatorial radius of Earth is 6.378136 ⋅ 10
A16: R1 | B16: W2 | C16: w2-q7 | D16: When was Python 3.0 released? | E16: text | F16: python 3.0, released in 2008 | G16: R1 | H16: 2 | I16: no | J16: yes | K16: https://en.wikipedia.org/wiki/Python_(programming_language) | L16: Python (programming language) > History | M16: 12), with the plus signifying (at least some) "backported security updates".[56] Python 3.0 was released on 3 December 2008, and was a major revision and not completely backward-compatible with earlier versions, with some new semantics and changed s
A17: R1 | B17: W2 | C17: w2-q8 | D17: Who won the men's downhill at the 2030 Winter Olympics? | E17: unanswerable | F17: (not in source) | G17: R1 | I17: n/a | J17: n/a | K17: https://en.wikipedia.org/wiki/Olympic_Games | L17: Olympic Games > References | M17: ↑ Mather, Victor (21 February 2018). "Desperately Seeking Skiers for a Budding Olympic Sport". The New York Times. Archived from the original on 11 March 2018. Retrieved 24 June 2018. ↑ "Men to compete in artistic swimming at Olympics for first time
A18: R1 | B18: W3 | C18: w3-q1 | D18: What was the minimum hourly wage for workers under 18 from April 2024 to March 2025? | E18: table | F18: £6.40 | G18: R1 | H18: 1 | I18: yes | J18: yes | K18: https://www.gov.uk/national-minimum-wage-rates | L18: National Minimum Wage and National Living Wage rates > Previous rates | M18: Rates between 1 April 2024 and 31 March 2026 Since 1 April 2024 the National Living Wage has been for those aged 21 and over. 21 and over 18 to 20 Under 18 Apprentice April 2025 to March 2026 £12.21 £10 £7.55 £7.55 April 2024 to March 2025
A19: R1 | B19: W3 | C19: w3-q2 | D19: Which taxable income band does the 40% higher rate of Income Tax cover? | E19: table | F19: £50,271 to £125,140 | G19: R1 | H19: 1 | I19: yes | J19: yes | K19: https://www.gov.uk/income-tax-rates | L19: Current rates and allowances | M19: Income Tax rates and bands The table shows the tax rates you pay in each band if you have a standard Personal Allowance of £12,570. Income tax bands are different if you live in Scotland. Band Taxable income Tax rate Personal Allowance Up to £
A20: R1 | B20: W3 | C20: w3-q3 | D20: How much Statutory Sick Pay can you get per week? | E20: text | F20: £123.25 | G20: R1 | H20: 1 | I20: yes | J20: yes | K20: https://www.gov.uk/statutory-sick-pay | M20: Overview You can get up to £123.25 per week Statutory Sick Pay (SSP) if you’re too ill to work. It’s paid by your employer for up to 28 weeks. This guide is also available in Welsh (Cymraeg). You cannot get less than the statutory amount. You can
A21: R1 | B21: W3 | C21: w3-q4 | D21: How many days of paid annual leave must a worker on a 5-day week receive? | E21: text | F21: at least 28 days | G21: R1 | H21: 1 | I21: yes | J21: yes | K21: https://www.gov.uk/holiday-entitlement-rights | L21: Entitlement | M21: Statutory annual leave entitlement Most workers who work a 5-day week must receive at least 28 days’ paid annual leave a year. This is the equivalent of 5.6 weeks of holiday.
A22: R1 | B22: W3 | C22: w3-q5 | D22: How long must you have worked for your employer to qualify for statutory redundancy pay? | E22: text | F22: at least 2 years | G22: R1 | H22: 1 | I22: yes | J22: yes | K22: https://www.gov.uk/calculate-your-redundancy-pay | M22: Calculate your statutory redundancy pay Calculate how much statutory redundancy you can get. It’s based on age, weekly pay and number of years in the job. Your weekly pay is the average you earned per week over the 12 weeks before the day you got y
A23: R1 | B23: W3 | C23: w3-q6 | D23: What is the first vehicle tax payment for a petrol car emitting 111 to 130g/km of CO2? | E23: table | F23: 111 to 130g/km + £455 | G23: R1 | H23: 2 | I23: no | J23: yes | K23: https://www.gov.uk/vehicle-tax-rate-tables | L23: Cars registered on or after 1 April 2017 | M23: First tax payment when you register the vehicle You’ll pay a rate based on a vehicle’s CO2 emissions the first time it’s registered. This also applies to some motorhomes. You have to pay a higher rate for diesel cars that do not meet the Real Driv
A24: R1 | B24: W3 | C24: w3-q7 | D24: From when can an employee make a request for flexible working? | E24: text | F24: from their first day in a job | G24: R1 | H24: 1 | I24: yes | J24: yes | K24: https://www.gov.uk/flexible-working | M24: Overview Flexible working is a way of working that suits an employee’s needs, for example having flexible start and finish times, or working from home. Flexible working rules are different in Northern Ireland. All employees have the legal right to
A25: R1 | B25: W3 | C25: w3-q8 | D25: What is the weekly rate of Statutory Paternity Pay? | E25: unanswerable | F25: (not in source) | G25: R1 | I25: n/a | J25: n/a | K25: https://www.gov.uk/statutory-sick-pay | M25: Statutory Sick Pay (SSP)
A26: R1 | B26: W4 | C26: w4-q1 | D26: What does HTTP status 418 I'm a teapot mean? | E26: list | F26: brew coffee with a teapot | G26: R1 | H26: 1 | I26: yes | J26: yes | K26: https://developer.mozilla.org/en-US/docs/Web/HTTP/Reference/Status | L26: HTTP response status codes > Client error responses | M26: ted data is not supported by the server, so the server is rejecting the request. 416 Range Not Satisfiable The ranges specified by the Range header field in the request cannot be fulfilled. It's possible that the range is outside the size of the ta
A27: R1 | B27: W4 | C27: w4-q2 | D27: What does HTTP status 429 mean? | E27: list | F27: too many requests in a given amount of time | G27: R1 | H27: 1 | I27: yes | J27: yes | K27: https://developer.mozilla.org/en-US/docs/Web/HTTP/Reference/Status | L27: HTTP response status codes > Client error responses | M27: sends an Upgrade header in a 426 response to indicate the required protocol(s). 428 Precondition Required The origin server requires the request to be conditional. This response is intended to prevent the 'lost update' problem, where a client GETs
A28: R1 | B28: W4 | C28: w4-q3 | D28: How must multiple Cache-Control directives be separated? | E28: text | F28: must be comma-separated | G28: R1 | H28: 1 | I28: yes | J28: yes | K28: https://developer.mozilla.org/en-US/docs/Web/HTTP/Reference/Headers/Cache-Control | L28: Cache-Control header | M28: Syntax Cache-Control: <directive>, <directive>, ... Cache directives follow these rules: Caching directives are case-insensitive. However, lowercase is recommended because some implementations do not recognize uppercase directives. Multiple direc
A29: R1 | B29: W4 | C29: w4-q4 | D29: What is a closure in JavaScript? | E29: text | F29: combination of a function bundled together | G29: R1 | H29: 1 | I29: yes | J29: yes | K29: https://developer.mozilla.org/en-US/docs/Web/JavaScript/Guide/Closures | M29: Closures A closure is the combination of a function bundled together (enclosed) with references to its surrounding state (the lexical environment). In other words, a closure gives a function access to its outer scope. In JavaScript, closures are cre
A30: R1 | B30: W4 | C30: w4-q5 | D30: How many mandatory arguments does the fetch() method take? | E30: text | F30: one mandatory argument | G30: R1 | H30: 2 | I30: no | J30: yes | K30: https://developer.mozilla.org/en-US/docs/Web/API/Fetch_API | L30: Fetch API > Specifications | M30: Fetch# fetch-method Fetch# deferred-fetch
A31: R1 | B31: W4 | C31: w4-q6 | D31: What does the HTTP QUERY method do? | E31: text | F31: the query method initiates a server-side query | G31: R1 | H31: 2 | I31: no | J31: yes | K31: https://developer.mozilla.org/en-US/docs/Web/HTTP/Reference/Methods | M31: HTTP request methods HTTP defines a set of request methods to indicate the purpose of the request and what is expected if the request is successful. Although they can also be nouns, these request methods are sometimes referred to as HTTP verbs. Each
A32: R1 | B32: W4 | C32: w4-q7 | D32: In MDN's CORS preflight example, what value is sent in the Access-Control-Max-Age header? | E32: code | F32: access-control-max-age: 86400 | G32: R1 | I32: no | J32: no | K32: https://developer.mozilla.org/en-US/docs/Web/HTTP/Guides/CORS | L32: Cross-Origin Resource Sharing (CORS) > The HTTP response headers | M32: Access-Control-Max-Age The Access-Control-Max-Age header indicates how long the results of a preflight request can be cached. For an example of a preflight request, see the above examples. Access-Control-Max-Age: <delta-seconds> The delta-seconds
A33: R1 | B33: W4 | C33: w4-q8 | D33: Which HTTP status code means Payment Accepted? | E33: unanswerable | F33: (not in source) | G33: R1 | I33: n/a | J33: n/a | K33: https://developer.mozilla.org/en-US/docs/Web/HTTP/Reference/Status | L33: HTTP response status codes > Successful responses | M33: . This is typically the response sent after POST requests, or some PUT requests. 202 Accepted The request has been received but not yet acted upon. It is noncommittal, since there is no way in HTTP to later send an asynchronous response indicating
A34: R1 | B34: F1 | C34: f1-q1 | D34: What are the layer, hidden size and attention head settings of BERT-base? | E34: text | F34: l=12, h=768, a=12 | G34: no index | I34: no | J34: no
A35: R1 | B35: F1 | C35: f1-q2 | D35: What percentage of WordPiece tokens does BERT mask during pre-training? | E35: text | F35: 15% of all wordpiece | G35: no index | I35: no | J35: no
A36: R1 | B36: F1 | C36: f1-q3 | D36: What GLUE score did BERT reach? | E36: text | F36: glue score to 80.5% | G36: no index | I36: no | J36: no
A37: R1 | B37: F1 | C37: f1-q4 | D37: Which corpora were used to pre-train BERT? | E37: text | F37: bookscorpus (800m words) | G37: no index | I37: no | J37: no
A38: R1 | B38: F1 | C38: f1-q5 | D38: What SQuAD v1.1 Test F1 did BERT achieve? | E38: text | F38: 93.2 | G38: no index | I38: no | J38: no
A39: R1 | B39: F1 | C39: f1-q6 | D39: How many total parameters does BERT-large have? | E39: text | F39: total parameters=340m | G39: no index | I39: no | J39: no
A40: R1 | B40: F1 | C40: f1-q7 | D40: How many GPUs were used to train GPT-4? | E40: unanswerable | F40: (not in source) | G40: no index | I40: n/a | J40: n/a
...

Sheet Answers
A1: Round | B1: Index used | C1: Question ID | D1: Question | E1: Reference answer | F1: Model answer | G1: Label (blind) | H1: Reason | I1: Supported by cited evidence | J1: Supported reason | K1: Cost (USD)
A2: R1 | B2: R1 | C2: w1-q1 | D2: Which class does the Python tutorial recommend for implementing a queue? | E2: collections.deque | F2: The Python tutorial recommends using `collections.deque` for implementing a queue because it is designed for fast appends and pops from both ends [S2, S1]. | G2: correct | H2: Names collections.deque. | I2: yes | J2: A cited chunk contains the expected phrase. | K2: 0.0005419
A3: R1 | B3: R1 | C3: w1-q3 | D3: What command does the tutorial use to create a virtual environment called tutorial-env? | E3: python -m venv tutorial-env | F3: The tutorial uses the command `python -m venv tutorial-env` to create a virtual environment named tutorial-env [S1]. | G3: correct | H3: Gives python -m venv tutorial-env. | I3: yes | J3: A cited chunk contains the expected phrase. | K3: 0.0005854
A4: R1 | B4: R1 | C4: w1-q8 | D4: On what date will Python 4.0 be released according to the tutorial? | E4: Not stated in the source. | F4: INSUFFICIENT_EVIDENCE. The provided text does not specify a release date for Python 4.0. In fact, according to Guido van Rossum, Python 4.0 will probably never exist [S3]. | G4: correct-abstain | H4: Declines; adds a cited aside that does not invent a date. | I4: n/a | J4: No answer to support. | K4: 0.0006461
A5: R1 | B5: R1 | C5: w2-q1 | D5: What is the elevation of Mount Everest in metres? | E5: 8,848.86 m (29,031.7 ft) | F5: The elevation of Mount Everest is 8,848.86 meters (29,031.7 ft) [S4]. This new official height was jointly announced by China and Nepal on December 8, 2020 [S2]. | G5: correct | H5: States 8,848.86 m. | I5: yes | J5: A cited chunk contains the expected phrase. | K5: 0.0007964
A6: R1 | B6: R1 | C6: w2-q3 | D6: What is the average discharge of the Amazon River? | E6: About 215,000 to 230,000 cubic meters per second. | F6: The Amazon River has an average discharge of about 215,000 to 230,000 cubic meters per second [S2]. Specifically, the average discharge at the estuary from 2003 to 2015 was 230,000 m³/s [S1]. If the Amazon and Rio Pará are considered a single water system, the total discharge at the Amazon Delta averages 223,700 m³/s, or 230,000 m³/s for the period 2003–2015 [S3]. | G6: correct | H6: States 215,000 to 230,000 m3/s. | I6: yes | J6: A cited chunk contains the expected phrase. | K6: 0.001366
A7: R1 | B7: R1 | C7: w2-q5 | D7: Who published the first generally accepted periodic table, and in what year? | E7: Dmitri Mendeleev, in 1869. | F7: The first generally accepted periodic table was published by the Russian chemist Dmitri Mendeleev in 1869 [S1]. | G7: correct | H7: Mendeleev, 1869. | I7: yes | J7: A cited chunk contains the expected phrase. | K7: 0.0005045
A8: R1 | B8: R1 | C8: w3-q1 | D8: What was the minimum hourly wage for workers under 18 from April 2024 to March 2025? | E8: £6.40 | F8: The minimum hourly wage for workers under 18 from April 2024 to March 2025 was £6.40 [S1]. | G8: correct | H8: States £6.40. | I8: yes | J8: A cited chunk contains the expected phrase. | K8: 0.00014812
A9: R1 | B9: R1 | C9: w3-q2 | D9: Which taxable income band does the 40% higher rate of Income Tax cover? | E9: £50,271 to £125,140 | F9: The 40% higher rate of Income Tax covers taxable income from £50,271 to £125,140 [S1]. | G9: correct | H9: States £50,271 to £125,140. | I9: yes | J9: A cited chunk contains the expected phrase. | K9: 0.0004699
A10: R1 | B10: R1 | C10: w3-q6 | D10: What is the first vehicle tax payment for a petrol car emitting 111 to 130g/km of CO2? | E10: £455 | F10: The first vehicle tax payment for a petrol car emitting 111 to 130g/km of CO2 is £455 [S2]. | G10: correct | H10: States £455 despite the flattened table. | I10: yes | J10: A cited chunk contains the expected phrase. | K10: 0.000811
A11: R1 | B11: R1 | C11: w4-q1 | D11: What does HTTP status 418 I'm a teapot mean? | E11: The server refuses the attempt to brew coffee with a teapot. | F11: The HTTP status 418 I'm a teapot means that the server refuses to brew coffee with a teapot [S1]. | G11: correct | H11: Refuses to brew coffee with a teapot. | I11: yes | J11: A cited chunk contains the expected phrase. | K11: 0.0005778
A12: R1 | B12: R1 | C12: w4-q4 | D12: What is a closure in JavaScript? | E12: The combination of a function bundled together with references to its surrounding state (the lexical environment). | F12: A closure in JavaScript is the combination of a function and its surrounding state (the lexical environment) [S1]. It allows a function to access its outer scope [S1]. Closures are created every time a function is created [S1]. This means that a function maintains access to variables that were in scope when the closure was created, even after the outer function has finished executing [S3, S5]. | G12: correct | H12: Function plus surrounding lexical environment. | I12: yes | J12: A cited chunk contains the expected phrase. | K12: 0.0006591
A13: R1 | B13: R1 | C13: w4-q8 | D13: Which HTTP status code means Payment Accepted? | E13: Not stated in the source (no such status code). | F13: INSUFFICIENT_EVIDENCE. The provided documents do not list an HTTP status code that means "Payment Accepted." They do mention "402 Payment Required," but this is a different meaning [S2]. | G13: correct-abstain | H13: Declines and notes 402 Payment Required is different. | I13: n/a | J13: No answer to support. | K13: 0.0005723
... A118: A3 | B118: A3 | C118: g2-q3 | D118: What does NIST SP 800-63B require for retina scanners at AAL3 in hospitals? | E118: Not stated in the source. | F118: INSUFFICIENT_EVIDENCE. The provided text does not specify requirements for retina scanners, nor does it mention hospitals. It only states general requirements for biometric factors at AAL3 [S1]. | G118: correct-abstain | H118: Declined; not in the source. | I118: n/a | J118: No answer to support. | K118: 0.0004691
A120: Total answer cost (USD) | K120: =SUM(K2:K118)
A121: Labels: correct, correct-abstain, partial, wrong, wrong-abstain. Scored blind by Claude with the spec 0004 rubric; rounds were hidden as X/Y. A1 (after the fixes) and A2 (extractor v4) were scored with the same rubric against the references, not blind.

Sheet Settings verdict
A1: Setting | B1: Where it shows | C1: Default | D1: Tested in | E1: Measured effect | F1: Verdict | G1: Recommendation
A2: If a file can't be read well | B2: Extract panel (visible) | C2: Stop and let me review (Balanced) | D2: R1 vs R1w, R3b, R5 | E2: The default blocked the whole files run in R1 because one ordinary government PDF (Census P60-279) was flagged for malformed tables. 'Publish the other files and show warnings' published it with warnings (R1w), but it does not publish the others when a required file cannot be read at all: R3b (OCR off) still failed the whole run. On websites (R5) it changed nothing because no page failed. | F2: Keep visible | G2: Keep the choice, but fix what it does: 'publish the others' should exclude any unreadable file, not only files marked optional (finding X3). Reconsider the default once X1 and X2 are fixed.
A3: Read scanned pages (OCR) | B3: Extract panel (visible) | C3: On | D3: R3b | E3: Turning it off made the scanned report unreadable and failed the whole files run (and every scan question). Leaving it on costs nothing for text PDFs: OCR ran only on the image-only pages. | F3: Candidate to remove | G3: Always run OCR when the server supports it; show a note only when OCR is unavailable.
A4: Languages in scanned pages | B4: Extract panel (visible when OCR is on) | C4: eng | D4: Not tested | E4: Only English sources and the English language pack were used. | F4: Keep visible | G4: Keep; it matters for non-English scans. Test with a non-English scan before changing it.
A5: Extractor version (v1 / v2) | B5: Upgrade callout only | C5: layout-ocr-v2 | D5: R2 | E5: Retrieval on the three files: Hit@5 16/19 with v1 vs 17/19 with v2 (v1 lost the scan's luminance-range question; both miss the same two Census table questions), Hit@1 8 vs 9. Answers: identical on the 8 file questions (6 correct, 1 correct-abstain, 1 wrong-abstain each). v2 also keeps headings and section paths that v1 does not. | F5: Keep in Advanced | G5: Keep v2 as the default and the upgrade as the only control; no new user setting.
A6: OCR resolution (DPI) | B6: Advanced | C6: 200 | D6: R3a (300) | E6: No change in any retrieval result, structure or answer on the scanned report. | F6: Candidate to remove | G6: Fix at 200 DPI; revisit only if a real low-quality scan shows a difference.
A7: Maximum OCR pages | B7: Advanced | C7: 50 | D7: R3a (100) | E7: No change: the scan had 10 pages. It only matters for scans longer than 50 pages, where the default would fail the file. | F7: Keep in Advanced | G7: Raise the default to the server maximum (100) and keep it in Advanced.
A8: Per-page OCR timeout | B8: Advanced | C8: 30 s | D8: Not changed | E8: No page came close: OCR took about 1-2 s per page. | F8: Candidate to remove | G8: Keep as a fixed server safety limit, not a user setting.
A9: Detect rotation / deskew | B9: Advanced | C9: On | D9: Not changed | E9: The real scan was upright; earlier synthetic tests showed rotation is needed for sideways scans and costs little. | F9: Candidate to remove | G9: Always on.
A10: Extraction strategy (Auto / Native / Layout-aware) | B10: Advanced | C10: Auto | D10: Not changed | E10: Auto handled the two-column paper, the report and the scan; Auto picked layout analysis on every text page. | F10: Candidate to remove | G10: Fix at Auto.
A11: Table evidence (Structured + Markdown / Markdown / Plain text) | B11: Advanced | C11: Structured + Markdown | D11: R4 (plain text) | E11: No change in any retrieval result (Hit@1 24, Hit@5 42 both); 684 vs 718 chunks. It does not apply to websites. | F11: Candidate to remove | G11: Fix at Structured + Markdown.
A12: Quality thresholds (empty pages, characters, OCR confidence, reading order, malformed tables) | B12: Advanced | C12: Balanced preset | D12: Indirectly (R1) | E12: 'Fail on malformed tables' is what blocked the Census report; 'suspicious reading order' only warned on the BERT paper and the report. | F12: Keep in Advanced | G12: Keep for experts; make the malformed-table check warn, not fail, until X2 is fixed.
... A14: Chunk size (target / maximum / overlap) | B14: Chunk stage | C14: 600 / 800 / 80 | D14: R6 (300 / 400 / 40) | E14: The only setting that moved results both ways: Hit@1 26 vs 24 and Hit@5 42 vs 42 overall; MDN improved (Hit@5 6 to 7, Hit@1 4 to 6), the scan improved at rank 1, two Wikipedia questions were gained and two lost, one BERT question was lost. Doubles the chunks and the embedding cost. | F14: Keep visible | G14: Keep 600 / 800 / 80 as the default and keep chunk size visible in the Chunk stage.

Sheet Findings
A1: ID | B1: Severity | C1: Finding | D1: Evidence | E1: Impact on users | F1: Next step | G1: After fixes (spec 0007) | H1: After-fixes evidence
A2: X1 | B2: High | C2: The recommended setting ('Stop and let me review') blocks an ordinary government report. | D2: R1 files run failed: Census P60-279 was flagged malformed_tables (19 tables) under the Balanced policy, so no file index was published. The free preview showed the same before any paid step. | E2: A user who uploads a normal statistical report with the defaults gets no index at all and must change a setting they do not understand. | F2: Fix X2; until then make malformed tables a warning in Balanced. | G2: Fixed | H2: A1 files run with 'Stop and let me review' published all three files; the Census report is no longer blocked (layout-ocr-v3).
A3: X2 | B3: High | C3: Borderless PDF tables lose their rows: whole columns are merged into one cell, and cells over 1,000 characters are cut. | D3: Census Table A-1 (page 21): one cell holds '74,580 95,450 110,800 56,030 ...' with the row names in a different cell; 19 tables were cut at the 1,000-character cell limit. f2-q4 and f2-q5 missed in every round; the answer model declined f2-q4 in both v1 and v2. | E3: Values from report tables cannot be matched to their rows, so table questions on real reports fail or are declined; data past the cut is lost. | F3: New extractor version: detect merged-column tables (cells with many line-separated values) and fall back to text lines for those tables instead of truncating. | G3: Fixed | H3: f2-q4 and f2-q5 now retrieve their Table A-1 row (rank 2 and 4; before: not in the top 5). f2-q4 answer changed from wrongly declined to correct ($110,800). Rotated landscape tables are kept whole but transposed (known limit).
A4: X3 | B4: High | C4: 'Publish the other files and show warnings' does not publish the others when a file cannot be read. | D4: R3b (OCR off) with warn-v1: the scanned report had no text, and the whole files run failed instead of excluding it. warn-v1 only excludes files marked optional. | E4: The plain-language choice in the Extract panel promises more than it does. | F4: Either exclude any unreadable file under this choice, or reword it to match the behaviour. | G4: Fixed (tests) | H4: Covered by PostgreSQL tests for files, S3 and Website runs: an unreadable item is skipped and the rest publish. Not re-run live: no A1 item failed.
